<?xml version="1.0" encoding="utf-8"?>
<!-- =================================================================================== -->
<!-- |    This document was autogenerated by xacro from /home/hwadong/catkin_ws/src/lwr_rviz_visualization/robots/kuka_lwr_arm.urdf.xml | -->
<!-- |    EDITING THIS FILE BY HAND IS NOT RECOMMENDED                                 | -->
<!-- =================================================================================== -->
<robot name="lwr" xmlns:body="http://playerstage.sourceforge.net/gazebo/xmlschema/#body" xmlns:controller="http://playerstage.sourceforge.net/gazebo/xmlschema/#controller" xmlns:gazebo="http://playerstage.sourceforge.net/gazebo/xmlschema/#gz" xmlns:geom="http://playerstage.sourceforge.net/gazebo/xmlschema/#geom" xmlns:interface="http://playerstage.sourceforge.net/gazebo/xmlschema/#interface" xmlns:joint="http://playerstage.sourceforge.net/gazebo/xmlschema/#joint" xmlns:model="http://playerstage.sourceforge.net/gazebo/xmlschema/#model" xmlns:physics="http://playerstage.sourceforge.net/gazebo/xmlschema/#physics" xmlns:renderable="http://playerstage.sourceforge.net/gazebo/xmlschema/#renderable" xmlns:rendering="http://playerstage.sourceforge.net/gazebo/xmlschema/#rendering" xmlns:sensor="http://playerstage.sourceforge.net/gazebo/xmlschema/#sensor" xmlns:xacro="http://www.ros.org/wiki/xacro" xmlns:xi="http://www.w3.org/2001/XInclude">
  <gazebo>
    <controller:gazebo_ros_controller_manager name="gazebo_controller_manager" plugin="libgazebo_ros_controller_manager.so">
      <alwaysOn>true</alwaysOn>
      <robotParam>robot_description</robotParam>
      <updateRate>1000.0</updateRate>
      <interface:audio name="gazebo_mechanism_control_dummy_iface"/>
    </controller:gazebo_ros_controller_manager>
  </gazebo>
  <material name="DarkGrey">
    <color rgba="0.3 0.3 0.3 1.0"/>
  </material>
  <material name="Black">
    <color rgba="0 0 0 1.0"/>
  </material>
  <material name="White">
    <color rgba="1.0 1.0 1.0 1.0"/>
  </material>
  <material name="Orange">
    <color rgba="1.0 0.487 0 1.0"/>
  </material>
  <material name="Silver">
    <color rgba="1.0 1.0 1.0 1.0"/>
  </material>
  <material name="Grey">
    <color rgba="0.7 0.7 0.7 1.0"/>
  </material>
  <material name="Blue">
    <color rgba="0.0 0.0 0.8 1.0"/>
  </material>
  <material name="HandGray">
    <color rgba="0.953 0.996 0.694 1.0"/>
  </material>
  <material name="SickBlue">
    <color rgba="0.3058 0.5921 0.7294 1.0"/>
  </material>
  <material name="Brown">
    <color rgba="0.823 0.706 0.549 1.0"/>
  </material>
  <link name="world"/>
  <joint name="arm_world_joint" type="fixed">
    <origin rpy="0.0 0.0 3.14159265359" xyz="0.0 0.0 0.0"/>
    <parent link="world"/>
    <child link="arm_world_link"/>
  </joint>
  <link name="arm_world_link">
    <inertial>
      <mass value="0.01"/>
      <com xyz="0 0 0"/>
      <inertia ixx="0.01" ixy="0.00" ixz="0.00" iyy="0.01" iyz="0.00" izz="0.01"/>
    </inertial>
    <visual>
      <origin rpy="0 0 0" xyz="0 0 0.0075"/>
      <geometry>
        <box size="0.275 0.275 0.015"/>
      </geometry>
      <material name="Grey"/>
    </visual>
    <collision>
      <origin rpy="0 0 0" xyz="0 0 0.0075"/>
      <geometry>
        <box size="0.275 0.275 0.015"/>
      </geometry>
    </collision>
  </link>
  <joint name="ground_world_joint" type="fixed">
    <origin rpy="0 0 0" xyz="0 0 0"/>
    <parent link="arm_world_link"/>
    <child link="ground_link"/>
  </joint>
  <!-- The table x size is 0.05 bigger than in reality to cope with calibration errors -->
  <link name="ground_link">
    <visual>
      <origin rpy="0 0 0" xyz="0.2725 0 -0.36"/>
      <geometry>
        <box size="0.85 1.6 0.72"/>
      </geometry>
      <material name="Brown"/>
    </visual>
    <collision>
      <origin rpy="0 0 0" xyz="0.2725 0 -0.36"/>
      <geometry>
        <box size="0.85 1.6 0.72"/>
      </geometry>
    </collision>
  </link>
  <!-- First (shoulder) element of the arm. Fixed to its parent. -->
  <joint name="arm_world_lwr_arm_base_joint" type="fixed">
    <origin rpy="0 0 0" xyz="0 0 0.015"/>
    <parent link="arm_world_link"/>
    <child link="calib_lwr_base_link"/>
  </joint>
  <link name="calib_lwr_base_link">
    <inertial>
      <mass value="2.0"/>
      <origin xyz="0 0 0.055"/>
      <inertia ixx="0.00381666666667" ixy="0" ixz="0" iyy="0.0036" iyz="0" izz="0.00381666666667"/>
    </inertial>
    <visual>
      <origin rpy="0 0 0" xyz="0 0 0"/>
      <geometry>
        <mesh filename="package://lwr_rviz_visualization/meshes/lwr/arm_base.dae"/>
      </geometry>
      <material name="White"/>
    </visual>
    <collision>
      <origin rpy="0 0 0" xyz="0 0 0"/>
      <geometry>
        <mesh filename="package://lwr_rviz_visualization/meshes/lwr/convex/arm_base_convex.stl"/>
      </geometry>
    </collision>
  </link>
  <gazebo reference="calib_lwr_base_link">
    <material value="kuka-lwr.material"/>
  </gazebo>
  <!-- Second segment of the arm. Joint along z-axis -->
  <joint name="lwr_arm_0_joint" type="revolute">
    <origin rpy="0 0 0" xyz="0 0 0.11"/>
    <axis xyz="0 0 1"/>
    <limit effort="204" lower="-2.96705972839" upper="2.96705972839" velocity="1.91986217719"/>
    <safety_controller k_position="30" k_velocity="30" soft_lower_limit="-2.79252680319" soft_upper_limit="2.79252680319"/>
    <dynamics damping="10.0"/>
    <parent link="calib_lwr_base_link"/>
    <child link="lwr_link_1"/>
  </joint>
  <link name="lwr_link_1">
    <inertial>
      <mass value="2.0"/>
      <origin rpy="0 0 0" xyz="0 -0.06 0.130"/>
      <inertia ixx="0.0136666666667" ixy="0" ixz="0" iyy="0.003" iyz="0" izz="0.0118666666667"/>
    </inertial>
    <visual>
      <origin rpy="0 0 0" xyz="0 0 0"/>
      <geometry>
        <mesh filename="package://lwr_rviz_visualization/meshes/lwr/arm_segment_a.dae"/>
      </geometry>
      <material name="White"/>
    </visual>
    <collision>
      <origin rpy="0 0 0" xyz="0 0 0"/>
      <geometry>
        <mesh filename="package://lwr_rviz_visualization/meshes/lwr/convex/arm_segment_a_convex.stl"/>
      </geometry>
    </collision>
  </link>
  <gazebo reference="lwr_link_1">
    <material value="kuka-lwr.material"/>
  </gazebo>
  <transmission name="lwr_arm_0_trans" type="SimpleTransmission">
    <actuator name="lwr_arm_0_motor"/>
    <joint name="lwr_arm_0_joint"/>
    <mechanicalReduction>1.0</mechanicalReduction>
  </transmission>
  <!-- Third segment of the arm. Joint along y-axis -->
  <joint name="lwr_arm_1_joint" type="revolute">
    <origin rpy="0 0 0" xyz="0 0 0.20"/>
    <axis xyz="0 1 0"/>
    <limit effort="306" lower="-2.09439510239" upper="2.09439510239" velocity="1.91986217719"/>
    <safety_controller k_position="30" k_velocity="30" soft_lower_limit="-1.91986217719" soft_upper_limit="1.91986217719"/>
    <dynamics damping="10.0"/>
    <parent link="lwr_link_1"/>
    <child link="lwr_link_2"/>
  </joint>
  <link name="lwr_link_2">
    <inertial>
      <mass value="2.0"/>
      <origin rpy="0 0 0" xyz="0 0.06 0.07"/>
      <inertia ixx="0.0136666666667" ixy="0" ixz="0" iyy="0.003" iyz="0" izz="0.0118666666667"/>
    </inertial>
    <visual>
      <origin rpy="3.14159265359 0 0" xyz="0 0 0.2"/>
      <geometry>
        <mesh filename="package://lwr_rviz_visualization/meshes/lwr/arm_segment_b.dae"/>
      </geometry>
      <material name="White"/>
    </visual>
    <collision>
      <origin rpy="3.14159265359 0 0" xyz="0 0 0.2"/>
      <geometry>
        <mesh filename="package://lwr_rviz_visualization/meshes/lwr/convex/arm_segment_b_convex.stl"/>
      </geometry>
    </collision>
  </link>
  <gazebo reference="lwr_link_2">
    <material value="kuka-lwr.material"/>
  </gazebo>
  <transmission name="lwr_arm_1_trans" type="SimpleTransmission">
    <actuator name="lwr_arm_1_motor"/>
    <joint name="lwr_arm_1_joint"/>
    <mechanicalReduction>1.0</mechanicalReduction>
  </transmission>
  <!-- Fourth element of the arm. z-axis -->
  <joint name="lwr_arm_2_joint" type="revolute">
    <origin rpy="0 0 0" xyz="0 0 0.20"/>
    <axis xyz="0 0 1"/>
    <limit effort="204" lower="-2.96705972839" upper="2.96705972839" velocity="2.26892802759"/>
    <safety_controller k_position="30" k_velocity="30" soft_lower_limit="-2.79252680319" soft_upper_limit="2.79252680319"/>
    <dynamics damping="10.0"/>
    <parent link="lwr_link_2"/>
    <child link="lwr_link_3"/>
  </joint>
  <link name="lwr_link_3">
    <inertial>
      <mass value="2.0"/>
      <origin rpy="0 0 0" xyz="0 0.06 0.130"/>
      <inertia ixx="0.0136666666667" ixy="0" ixz="0" iyy="0.003" iyz="0" izz="0.0118666666667"/>
    </inertial>
    <visual>
      <origin rpy="0 0 3.14159265359" xyz="0 0 0"/>
      <geometry>
        <mesh filename="package://lwr_rviz_visualization/meshes/lwr/arm_segment_a.dae"/>
      </geometry>
      <material name="White"/>
    </visual>
    <collision>
      <origin rpy="0 0 3.14159265359" xyz="0 0 0"/>
      <geometry>
        <mesh filename="package://lwr_rviz_visualization/meshes/lwr/convex/arm_segment_a_convex.stl"/>
      </geometry>
    </collision>
  </link>
  <gazebo reference="lwr_link_3">
    <material value="kuka-lwr.material"/>
  </gazebo>
  <transmission name="lwr_arm_2_trans" type="SimpleTransmission">
    <actuator name="lwr_arm_2_motor"/>
    <joint name="lwr_arm_2_joint"/>
    <mechanicalReduction>1.0</mechanicalReduction>
  </transmission>
  <!-- fifth element of the arm. x-axis -->
  <joint name="lwr_arm_3_joint" type="revolute">
    <origin rpy="0 0 0" xyz="0 0 0.20"/>
    <axis xyz="0 -1 0"/>
    <limit effort="306" lower="-2.09439510239" upper="2.09439510239" velocity="2.26892802759"/>
    <safety_controller k_position="30" k_velocity="30" soft_lower_limit="-1.91986217719" soft_upper_limit="1.91986217719"/>
    <dynamics damping="10.0"/>
    <parent link="lwr_link_3"/>
    <child link="lwr_link_4"/>
  </joint>
  <link name="lwr_link_4">
    <inertial>
      <mass value="2.0"/>
      <origin rpy="0 0 0" xyz="0 -0.06 0.07"/>
      <inertia ixx="0.0136666666667" ixy="0" ixz="0" iyy="0.003" iyz="0" izz="0.0118666666667"/>
    </inertial>
    <visual>
      <origin rpy="0 3.14159265359 0" xyz="0 0 0.2"/>
      <geometry>
        <mesh filename="package://lwr_rviz_visualization/meshes/lwr/arm_segment_b.dae"/>
      </geometry>
      <material name="White"/>
    </visual>
    <collision>
      <origin rpy="0 3.14159265359 0" xyz="0 0 0.2"/>
      <geometry>
        <mesh filename="package://lwr_rviz_visualization/meshes/lwr/convex/arm_segment_b_convex.stl"/>
      </geometry>
    </collision>
  </link>
  <gazebo reference="lwr_link_4">
    <material value="kuka-lwr.material"/>
  </gazebo>
  <transmission name="lwr_arm_3_trans" type="SimpleTransmission">
    <actuator name="lwr_arm_3_motor"/>
    <joint name="lwr_arm_3_joint"/>
    <mechanicalReduction>1.0</mechanicalReduction>
  </transmission>
  <!-- Sixth element of the arm. z-axis -->
  <joint name="lwr_arm_4_joint" type="revolute">
    <origin rpy="0 0 0" xyz="0 0 0.20"/>
    <axis xyz="0 0 1"/>
    <limit effort="204" lower="-2.96705972839" upper="2.96705972839" velocity="2.26892802759"/>
    <safety_controller k_position="30" k_velocity="30" soft_lower_limit="-2.79252680319" soft_upper_limit="2.79252680319"/>
    <dynamics damping="10.0"/>
    <parent link="lwr_link_4"/>
    <child link="lwr_link_5"/>
  </joint>
  <link name="lwr_link_5">
    <inertial>
      <mass value="2.0"/>
      <origin rpy="0 0 0" xyz="0 0 0.124"/>
      <inertia ixx="0.0126506666667" ixy="0" ixz="0" iyy="0.003" iyz="0" izz="0.0108506666667"/>
    </inertial>
    <visual>
      <origin rpy="0 0 0" xyz="0 0 0"/>
      <geometry name="lwr_arm_5_geom">
        <mesh filename="package://lwr_rviz_visualization/meshes/lwr/arm_segment_last.dae"/>
      </geometry>
      <material name="White"/>
    </visual>
    <collision>
      <origin rpy="0 0 0" xyz="0 0 0"/>
      <geometry>
        <mesh filename="package://lwr_rviz_visualization/meshes/lwr/convex/arm_segment_last_convex.stl"/>
      </geometry>
    </collision>
  </link>
  <gazebo reference="lwr_link_5">
    <material value="kuka-lwr.material"/>
  </gazebo>
  <transmission name="lwr_arm_4_trans" type="SimpleTransmission">
    <actuator name="lwr_arm_4_motor"/>
    <joint name="lwr_arm_4_joint"/>
    <mechanicalReduction>1.0</mechanicalReduction>
  </transmission>
  <joint name="lwr_arm_5_joint" type="revolute">
    <origin rpy="0 0 0" xyz="0 0 0.19"/>
    <axis xyz="0 1 0"/>
    <limit effort="306" lower="-2.09439510239" upper="2.09439510239" velocity="3.14159265359"/>
    <safety_controller k_position="30" k_velocity="30" soft_lower_limit="-1.91986217719" soft_upper_limit="1.91986217719"/>
    <dynamics damping="10.0"/>
    <parent link="lwr_link_5"/>
    <child link="lwr_link_6"/>
  </joint>
  <link name="lwr_link_6">
    <inertial>
      <mass value="0.2"/>
      <origin rpy="0 0 0" xyz="0 0 0.0625"/>
      <inertia ixx="0.000520833333333" ixy="0" ixz="0" iyy="0.000520833333333" iyz="0" izz="0.000520833333333"/>
    </inertial>
    <visual>
      <origin rpy="0 0 0" xyz="0 0 0"/>
      <geometry>
        <mesh filename="package://lwr_rviz_visualization/meshes/lwr/arm_wrist.dae"/>
      </geometry>
      <material name="Grey"/>
    </visual>
    <collision>
      <origin rpy="0 0 0" xyz="0 0 0"/>
      <geometry>
        <mesh filename="package://lwr_rviz_visualization/meshes/lwr/convex/arm_wrist_convex.stl"/>
      </geometry>
    </collision>
  </link>
  <gazebo reference="lwr_link_6">
    <material value="kuka-lwr.material"/>
  </gazebo>
  <transmission name="lwr_arm_5_trans" type="SimpleTransmission">
    <actuator name="lwr_arm_5_motor"/>
    <joint name="lwr_arm_5_joint"/>
    <mechanicalReduction>1.0</mechanicalReduction>
  </transmission>
  <joint name="lwr_arm_6_joint" type="revolute">
    <origin rpy="0 0 0" xyz="0 0 0.078"/>
    <axis xyz="0 0 1"/>
    <limit effort="204" lower="-2.96705972839" upper="2.96705972839" velocity="3.14159265359"/>
    <safety_controller k_position="30" k_velocity="30" soft_lower_limit="-2.79252680319" soft_upper_limit="2.79252680319"/>
    <dynamics damping="1.0"/>
    <parent link="lwr_link_6"/>
    <child link="lwr_link_7"/>
  </joint>
  <link name="lwr_link_7">
    <inertial>
      <mass value="0.2"/>
      <origin xyz="0 0 0"/>
      <inertia ixx="0.0333333333333" ixy="0" ixz="0" iyy="0.0333333333333" iyz="0" izz="0.0333333333333"/>
    </inertial>
    <visual>
      <origin rpy="0 0 -0.785398163397" xyz="0 0 0"/>
      <geometry>
        <mesh filename="package://lwr_rviz_visualization/meshes/lwr/arm_flanche.dae"/>
      </geometry>
      <material name="Grey"/>
    </visual>
    <collision>
      <origin rpy="0 0 -0.785398163397" xyz="0 0 0"/>
      <geometry>
        <mesh filename="package://lwr_rviz_visualization/meshes/lwr/convex/arm_flanche_convex.stl"/>
      </geometry>
    </collision>
  </link>
  <gazebo reference="lwr_arm_7_link">
    <material value="kuka-lwr.material"/>
  </gazebo>
  <transmission name="lwr_arm_6_trans" type="SimpleTransmission">
    <actuator name="lwr_arm_6_motor"/>
    <joint name="lwr_arm_6_joint"/>
    <mechanicalReduction>1.0</mechanicalReduction>
  </transmission>
  <!-- Black cylindric connector 
    <joint name="black_connector_joint" type="fixed">
      <origin xyz="0.0 0.0 0.005" rpy="0.0 0.0 0.0"/>
      <parent link="${name}_arm_7_link"/>
      <child link="black_connector_link"/>
    </joint> 
	
    <link name="black_connector_link">
	  <visual>
        <origin xyz="0.0 0.0 0.0" rpy="0.0 0.0 0.0"/>
		<geometry>
		  <cylinder length="0.01" radius="0.0311"/>
		</geometry>
		<material name="black">
		  <color rgba="0 0 0 1"/>
		</material>
	  </visual>
	  <collision>
        <origin xyz="0.0 0.0 0.0" rpy="0.0 0.0 0.0"/>
		<geometry>
		  <cylinder length="0.01" radius="0.0311"/>
		</geometry>
	  </collision>
	</link>-->
  <!-- FWS115 adapter 
    <joint name="fws115_adapter_joint" type="fixed">
      <origin xyz="0.0 0.0 0.0155" rpy="0.0 0.0 ${1/2 * M_PI}"/>
      <parent link="black_connector_link"/>
      <child link="fws115_adapter_link"/>
    </joint> 
	
    <link name="fws115_adapter_link">
	  <visual>
        <origin xyz="0.0 0.0 0.0" rpy="0.0 0.0 0.0"/>
		<geometry>
		  <cylinder length="0.021" radius="0.045"/>
		</geometry>
		<material name="Grey"/>
	  </visual>
	  <collision>
        <origin xyz="0.0 0.0 0.0" rpy="0.0 0.0 0.0"/>
		<geometry>
		  <cylinder length="0.021" radius="0.045"/>
		</geometry>
	  </collision>
	</link>-->
  <!-- New adapter -->
  <joint name="box_adapter_joint" type="fixed">
    <origin rpy="0.0 0.0 0.0" xyz="0.0 0.0 0.005"/>
    <parent link="lwr_link_7"/>
    <child link="box_adapter_link"/>
  </joint>
  <link name="box_adapter_link">
    <visual>
      <origin rpy="0.0 0.0 0.0" xyz="0.0 0.0 0.0"/>
      <geometry>
        <box size="0.07 0.07 0.016"/>
      </geometry>
      <material name="white">
        <color rgba="1 1 1 1"/>
      </material>
    </visual>
    <collision>
      <origin rpy="0.0 0.0 0.0" xyz="0.0 0.0 0.0"/>
      <geometry>
        <box size="0.07 0.07 0.016"/>
      </geometry>
    </collision>
  </link>
  <!-- BASE LINK -->
  <joint name="wsg50_gripper_base_joint" type="fixed">
    <origin rpy="0 0 0.7854" xyz="0 0 0.008"/>
    <parent link="box_adapter_link"/>
    <child link="wsg50_gripper_base_link"/>
  </joint>
  <link name="wsg50_gripper_base_link">
    <inertial>
      <mass value="1.2"/>
      <origin xyz="0 0 0"/>
      <!--inertia ixx="1.0" ixy="0.0" ixz="0.0"
               iyy="100.0" iyz="0.0" 
               izz="1.0" /-->
      <inertia ixx="1.0" ixy="0.0" ixz="0.0" iyy="1.0" iyz="0.0" izz="1.0"/>
    </inertial>
    <visual>
      <origin rpy="0 0 0" xyz="0.0 0 0"/>
      <geometry>
        <mesh filename="package://lwr_rviz_visualization/meshes/wsg50_gripper/WSG50_110.dae" scale="1 1 1"/>
        <!--box size="0.146 0.05 0.0735"/-->
      </geometry>
      <material name="grey">
        <color rgba="0.7 0.7 0.7 1"/>
      </material>
    </visual>
    <collision>
      <origin rpy="0 0 0" xyz="0.0 0 0"/>
      <geometry>
        <!--box size="0.146 0.05 0.0735"/-->
        <mesh filename="package://lwr_rviz_visualization/meshes/wsg50_gripper/WSG50_110.stl" scale="1 1 1"/>
      </geometry>
    </collision>
  </link>
  <gazebo reference="wsg50_gripper_base_link">
    <material>Gazebo/Grey</material>
    <turnGravityOff>false</turnGravityOff>
  </gazebo>
  <!-- GRIPPER LEFT -->
  <joint name="wsg50_gripper_base_joint_left" type="prismatic">
    <limit effort="1.0" lower="-0.055" upper="-0.0027" velocity="1.0"/>
    <origin rpy="0 0 0" xyz="0 0 0"/>
    <!--origin xyz="-0.0067 0 0.049" rpy="0 0 0" /-->
    <parent link="wsg50_gripper_base_link"/>
    <child link="wsg50_gripper_left"/>
    <dynamics damping="100" friction="100"/>
    <axis xyz="1 0 0"/>
    <limit effort="100" velocity="100"/>
  </joint>
  <transmission name="base_trans_left" type="pr2_mechanism_model/SimpleTransmission">
    <actuator name="base_motor_left"/>
    <joint name="wsg50_gripper_joint_left"/>
    <mechanicalReduction>1</mechanicalReduction>
    <motorTorqueConstant>1</motorTorqueConstant>
  </transmission>
  <link name="wsg50_gripper_left">
    <inertial>
      <mass value="0.1"/>
      <origin xyz="0 0 0"/>
      <inertia ixx="1.0" ixy="0.0" ixz="0.0" iyy="1.0" iyz="0.0" izz="1.0"/>
    </inertial>
    <visual>
      <origin rpy="0 0 0" xyz="0.0 0 0"/>
      <geometry>
        <mesh filename="package://lwr_rviz_visualization/meshes/wsg50_gripper/GUIDE_WSG50_110.dae" scale="0.001 0.001 0.001"/>
        <!--box size="0.0175 0.03 0.024"/-->
      </geometry>
      <material name="black">
        <color rgba="0 0 0 1"/>
      </material>
    </visual>
    <collision>
      <origin rpy="0 0 0" xyz="0 0 0"/>
      <geometry>
        <!--box size="0.0175 0.03 0.024"/-->
        <mesh filename="package://lwr_rviz_visualization/meshes/wsg50_gripper/GUIDE_WSG50_110.stl" scale="0.001 0.001 0.001"/>
      </geometry>
    </collision>
  </link>
  <gazebo reference="wsg50_gripper_left">
    <material>Gazebo/Blue</material>
    <turnGravityOff>false</turnGravityOff>
  </gazebo>
  <!-- LEFT FINGER -->
  <joint name="wsg50_gripper_guide_joint_finger_left" type="fixed">
    <origin rpy="0 0 0" xyz="0 0 0.023"/>
    <parent link="wsg50_gripper_left"/>
    <child link="wsg50_gripper_finger_left"/>
    <dynamics damping="100" friction="100"/>
    <axis xyz="1 0 0"/>
    <limit effort="100" velocity="100"/>
  </joint>
  <link name="wsg50_gripper_finger_left">
    <inertial>
      <mass value="0.1"/>
      <origin xyz="0 0 0"/>
      <inertia ixx="1.0" ixy="0.0" ixz="0.0" iyy="1.0" iyz="0.0" izz="1.0"/>
    </inertial>
    <visual>
      <origin rpy="0 0 0" xyz="0.0 0 0"/>
      <geometry>
        <mesh filename="package://lwr_rviz_visualization/meshes/wsg50_gripper/WSG-FMF.dae" scale="0.001 0.001 0.001"/>
      </geometry>
      <material name="black">
        <color rgba="0 0 0 1"/>
      </material>
    </visual>
    <collision>
      <origin rpy="0 0 0" xyz="0 0 0"/>
      <geometry>
        <mesh filename="package://lwr_rviz_visualization/meshes/wsg50_gripper/WSG-FMF.stl" scale="0.001 0.001 0.001"/>
      </geometry>
    </collision>
  </link>
  <gazebo reference="wsg50_gripper_finger_left">
    <material>Gazebo/Blue</material>
    <turnGravityOff>false</turnGravityOff>
  </gazebo>
  <!-- GRIPPER RIGHT -->
  <joint name="wsg50_gripper_base_joint_right" type="prismatic">
    <limit effort="1.0" lower="0.0027" upper="0.055" velocity="1.0"/>
    <origin rpy="0 0 3.14159" xyz="0 0 0"/>
    <parent link="wsg50_gripper_base_link"/>
    <child link="wsg50_gripper_right"/>
    <axis xyz="-1 0 0"/>
    <dynamics damping="100" friction="100"/>
    <limit effort="100" velocity="100"/>
  </joint>
  <transmission name="base_trans_right" type="pr2_mechanism_model/SimpleTransmission">
    <actuator name="base_motor_right"/>
    <joint name="wsg50_gripper_joint_right"/>
    <mechanicalReduction>1</mechanicalReduction>
    <motorTorqueConstant>1</motorTorqueConstant>
  </transmission>
  <link name="wsg50_gripper_right">
    <inertial>
      <mass value="0.1"/>
      <origin xyz="0 0 0"/>
      <inertia ixx="1.0" ixy="0.0" ixz="0.0" iyy="1.0" iyz="0.0" izz="1.0"/>
    </inertial>
    <visual>
      <origin rpy="0 0 0" xyz="0.0 0 0"/>
      <geometry>
        <mesh filename="package://lwr_rviz_visualization/meshes/wsg50_gripper/GUIDE_WSG50_110.dae" scale="0.001 0.001 0.001"/>
      </geometry>
      <material name="black">
        <color rgba="0 0 0 1"/>
      </material>
    </visual>
    <collision>
      <origin rpy="0 0 0" xyz="0 0 0"/>
      <geometry>
        <mesh filename="package://lwr_rviz_visualization/meshes/wsg50_gripper/GUIDE_WSG50_110.stl" scale="0.001 0.001 0.001"/>
      </geometry>
    </collision>
  </link>
  <gazebo reference="wsg50_gripper_right">
    <material>Gazebo/White</material>
    <turnGravityOff>false</turnGravityOff>
  </gazebo>
  <!-- RIGHT FINGER -->
  <joint name="wsg50_gripper_guide_joint_finger_right" type="fixed">
    <origin rpy="0 0 0" xyz="0 0 0.023"/>
    <parent link="wsg50_gripper_right"/>
    <child link="wsg50_gripper_finger_right"/>
    <dynamics damping="100" friction="100"/>
    <axis xyz="1 0 0"/>
    <limit effort="100" velocity="100"/>
  </joint>
  <link name="wsg50_gripper_finger_right">
    <inertial>
      <mass value="0.1"/>
      <origin xyz="0 0 0"/>
      <inertia ixx="1.0" ixy="0.0" ixz="0.0" iyy="1.0" iyz="0.0" izz="1.0"/>
    </inertial>
    <visual>
      <origin rpy="0 0 0" xyz="0.0 0 0"/>
      <geometry>
        <mesh filename="package://lwr_rviz_visualization/meshes/wsg50_gripper/WSG-FMF.dae" scale="0.001 0.001 0.001"/>
      </geometry>
      <material name="black">
        <color rgba="0 0 0 1"/>
      </material>
    </visual>
    <collision>
      <origin rpy="0 0 0" xyz="0 0 0"/>
      <geometry>
        <mesh filename="package://lwr_rviz_visualization/meshes/wsg50_gripper/WSG-FMF.stl" scale="0.001 0.001 0.001"/>
      </geometry>
    </collision>
  </link>
  <gazebo reference="wsg50_gripper_finger_right">
    <material>Gazebo/White</material>
    <turnGravityOff>false</turnGravityOff>
  </gazebo>
  <!-- Gazebo controllers -->
  <!--gazebo>
     <controller:gazebo_ros_time name="gazebo_ros_time" plugin="libgazebo_ros_time.so">
       <alwaysOn>true</alwaysOn>
       <updateRate>1000.0</updateRate>
       <interface:audio name="dummy_gazebo_ros_time_iface_should_not_be_here"/>
     </controller:gazebo_ros_time-->
  <!-- PR2_ACTARRAY 
  <gazebo>
     <controller:gazebo_ros_controller_manager name="gazebo_ros_controller_manager" plugin="libgazebo_ros_controller_manager.so">
       <alwaysOn>true</alwaysOn>
       <updateRate>1000.0</updateRate>
       <interface:audio name="gazebo_ros_controller_manager_dummy_iface" />
     </controller:gazebo_ros_controller_manager>
  </gazebo> -->
  <!--  <joint name="${name}_arm_hand_fixed_joint" type="fixed">
      <origin xyz="${right * 0.075} 0.075 -0.094"
              rpy="${0.5*right*M_PI} 0 ${(0.5 + 0.25*right)*M_PI}"/>
      <parent link="${name}_arm_7_link"/>
      <child link="${name}_arm_hand_link"/>
    </joint>

    <link name="${name}_arm_hand_link">
      <inertial>
        <mass value="0.01"/>
        <origin xyz="0 0 0"/>
        <cuboid_inertia_def length="1" width="1" height="1"
                            mass="0.01"/>
      </inertial>

      <visual>
        <origin xyz="0 0 0" rpy="0 0 0"/>
        <geometry>
          <box size="0.001 0.001 0.001"/>
        </geometry>
        <material name="Grey"/>
      </visual>

      <collision>
        <origin xyz="0 0 0" rpy="0 0 0"/>
        <geometry>
          <mesh filename="package://lwr_rviz_visualization/meshes/lwr/convex/hand_convex.stl"/>
        </geometry>
      </collision>
    </link> -->
  <!-- Cut background 
   <link name="wall1"> 
        <visual>
            <geometry>
                <box size="3 4 2" />
            </geometry>
        <material name="Orange"/>
        </visual>>
        <collision>
            <geometry>
                <box size="3 4 2" />
            </geometry>
        </collision>>
    </link>

    <joint name="wall1_joint" type="fixed" >
        <origin xyz="2.5 0 0" rpy="0 0 0"/>
        <parent link="arm_world_link"/>
        <child link="wall1"/>
    </joint> 

   <link name="wall2"> 
        <visual>
            <geometry>
                <box size="3 4 2" />
            </geometry>
        <material name="Orange"/>
        </visual>>
        <collision>
            <geometry>
                <box size="3 4 2" />
            </geometry>
        </collision>>
    </link>

    <joint name="wall2_joint" type="fixed" >
        <origin xyz="1.5 -2.3 0" rpy="0 0 1.5708"/>
        <parent link="arm_world_link"/>
        <child link="wall2"/>
    </joint> 

   END Cut background -->
</robot>

